Workbook
Name Key: リスト!$B$3:$B$4
Name フォーマット: リスト!$K$3:$K$8
Name プロトコル: リスト!$J$3:$J$11
Name 必須: リスト!$G$3:$G$4
Name 操作内容: リスト!$L$3:$L$8
Name 符号: リスト!$I$3:$I$6
Name 改行コード: リスト!$Q$3:$Q$6
Name 桁数表記: リスト!$V$3:$V$5
Name 空ファイル生成: リスト!$S$3:$S$6
Name 括り文字: リスト!$R$3:$R$7
Name 連携方式: リスト!$A$3:$A$8
Name 連携区分: リスト!$N$3:$N$5
Name 起動契機: リスト!$M$3:$M$10
Name 属性: リスト!$C$3:$C$8
Name 文字コード: リスト!$P$3:$P$7
Name 文字埋: リスト!$H$3:$H$7
Name 文字種別: リスト!$D$3:$D$6
Name 項目属性: リスト!$U$3:$U$11
Name 小数部: リスト!$F$3:$F$5
Name 有り無し: リスト!$E$3:$E$5
Name 有無: リスト!$T$3:$T$5
Name 再処理単位: リスト!$O$3:$O$6

Sheet 表紙
E11: KAPS2再構築PJ
E12: インターフェース項目定義書
C16: IFID | D16: IFZ9000120
C17: IF名称 | D17: 国内出荷指示送信データ（積送）
C18: 連携方式 | D18: ファイル連携

Sheet IFレイアウト
A1: IFID | D1: インターフェース名称
A2: =IF(表紙!D16<>"",表紙!D16,"") | D2: =IF(表紙!D17<>"",表紙!D17,"")
A4: No | B4: Key | C4: 項目名称 | D4: 技術名称 | E4: 属性 | F4: 文字種別 | G4: 文字数 | H4: Byte数 | I4: 小数桁 | J4: 小数点 | K4: 小数部 | L4: 桁区切り | M4: 必須 | N4: 文字埋 | O4: 符号 | P4: 階層構造 | Q4: 繰り返し数 | R4: 書式設定 | S4: 備考
A5: =ROW()-4
A6: =ROW()-4
A7: =ROW()-4
A8: =ROW()-4
A9: =ROW()-4
A10: =ROW()-4
A11: =ROW()-4
A12: =ROW()-4
A13: =ROW()-4
A14: =ROW()-4
A15: =ROW()-4
A16: =ROW()-4
... A59: =ROW()-4

Sheet 項目マッピング
A1: IFID | C1: インターフェース名称 | O1: →印刷範囲外（対向先とのセッション時に利用）
A2: =IF(表紙!D16<>"",表紙!D16,"") | C2: =IF(表紙!D17<>"",表紙!D17,"")
A4: 連携元 | G4: 連携元№ | H4: 変換 | I4: 連携先 | P4: (補足）対向先調整メモ
A5: 部品SAP | H5: 変換仕様 | I5: 倉庫システム | P5: 現行からの変更内容 | S5: 部品SAP再現不可情報 | U5: 備考
A6: № | B6: 項目名称 | C6: 構造 | D6: 技術名称 | E6: 文字数 | F6: 属性 | I6: № | J6: 項目名称 | K6: 構造 | L6: 技術名称 | M6: 文字数 | N6: 属性 | P6: 桁数 | Q6: コード体系 | R6: 補足・その他 | S6: No. | T6: 分類 | V6: マッチソース
A7: S010 | G7: S010 | H7: 固定値「S1」 | I7: S010 | M7: 2 | N7: 文字(半角のみ)
A8: S020 | G8: S020 | H8: 固定値「60」 | I8: S020 | M8: 2 | N8: 文字(半角のみ)
A9: S030 | B9: アドオンテーブル | G9: S030 | H9: 変換テーブルを使用 | I9: S030 | M9: 3 | N9: 文字(半角のみ)
A10: S040 | B10: プラント | C10: MATDOC | D10: WERKS | E10: 4 | F10: CHAR | G10: S040 | H10: 出庫プラントに合わせ下記６桁得意先コードを設定 ⇒KAPSでは倉庫マスターに設定されている得意先（クボタを示すコード） 倉庫→得意先 11→900210 28→900280 31→900580 41→901740 61→901670 71→903570 | I10: S040 | J10: 引当倉庫・親倉庫 | K10: RJ071 | L10: CHKASOKOYA | M10: 6 | N10: 文字(半角のみ) | V10: 精确
A11: S050 | G11: S050 | H11: 固定値「1」 | I11: S050 | M11: 1 | N11: 文字(半角のみ)
A12: S060 | B12: 伝票の伝票日付 | C12: MATDOC | D12: BLDAT | E12: 8 | F12: DATS | G12: S060 | I12: S060 | J12: データ作成日 | K12: RJ071 | L12: DDTASSI | M12: 6 | N12: 文字(半角のみ) | V12: 精确
A13: S070 | G13: S070 | H13: ブランク | I13: S070 | M13: 8 | N13: 文字(半角のみ)
A14: S080 | B14: 地域 (都道府県) | C14: KNA1 | D14: REGIO | E14: 3 | F14: CHAR | G14: S080 | H14: S090納所コードに設定したコードのBPマスタから取得 | I14: S080 | J14: 府県コード | K14: RJ071 | L14: BFUK | M14: 2 | N14: 文字(半角のみ) | V14: 精确
A15: S090 | B15: プラント | C15: MATDOC | D15: WERKS | E15: 4 | F15: CHAR | G15: S090 | H15: 出庫プラントに合わせ下記３桁納所コードを設定 ⇒KAPSでは倉庫マスターに設定されている納所 倉庫→得意先 納所 11→900210 360 28→900280 651 31→900580 002 41→901740 100 61→901670 001 71→903570 001 | I15: S090 | J15: 引当倉庫・親倉庫 | K15: RJ071 | L15: CHKASOKOYA | M15: 3 | N15: 文字(半角のみ) | V15: 精确
A16: S0100 | B16: 名称1＋名称2 (国際バージョン：カナ) | C16: ADRC ADRC | D16: NAME1 NAME2 | E16: 40 40 | F16: CHAR CHAR | G16: S0100 | H16: S090納所コードに設定したコードのBPマスタから取得 | I16: S0100 | J16: 納所名 | K16: RJ071 | L16: NNOS | M16: 40 | N16: 文字(半角のみ) | V16: 精确
A17: S0110 | B17: 都道府県＋市区町村 (国際バージョン：カナ) | C17: ADRC ADRC | D17: CITY1 STREET | E17: 40 60 | F17: CHAR CHAR | G17: S0110 | H17: S090納所コードに設定したコードのBPマスタから取得 | I17: S0110 | J17: 納所住所 | K17: RJ071 | L17: JNOS | M17: 40 | N17: 文字(半角のみ) | V17: 精确
A18: S0120 | G18: S0120 | H18: ブランク | I18: S0120 | M18: 6 | N18: 文字(半角のみ)
A19: S0130 | G19: S0130 | H19: ブランク | I19: S0130 | M19: 1 | N19: 文字(半角のみ)
A20: S0140 | G20: S0140 | H20: ブランク | I20: S0140 | M20: 1 | N20: 文字(半角のみ)
A21: S0150 | G21: S0150 | H21: ブランク | I21: S0150 | M21: 1 | N21: 文字(半角のみ)
A22: S0160 | G22: S0160 | H22: 非標準（※入出庫伝票のみ起票の前提） | I22: S0160 | M22: 8 | N22: 文字(半角のみ)
A23: S0170 | B23: 名称1＋名称2 (国際バージョン：カナ) | C23: ADRC ADRC | D23: NAME1 NAME2 | E23: 40 40 | F23: CHAR CHAR | G23: S0170 | H23: S040得意先コードに設定したコードのBPマスタから取得 | I23: S0170 | J23: 納所名 | K23: RJ071 | L23: NNOS | M23: 20 | N23: 文字(半角のみ) | V23: 精确
A24: S0180 | B24: 伝票の伝票日付 | C24: MATDOC | D24: BLDAT | E24: 8 | F24: DATS | G24: S0180 | H24: YYMMDDに編集 | I24: S0180 | J24: データ作成日 | K24: RJ071 | L24: DDTASSI | M24: 6 | N24: 文字(半角のみ) | V24: 精确
A25: S0190 | G25: S0190 | H25: ブランク | I25: S0190 | M25: 6 | N25: 文字(半角のみ)
A26: S0200 | G26: S0200 | H26: ブランク | I26: S0200 | M26: 4 | N26: 文字(半角のみ)
A27: S0210 | G27: S0210 | H27: ブランク | I27: S0210 | M27: 4 | N27: 文字(半角のみ)
A28: S0220 | G28: S0220 | H28: ブランク | I28: S0220 | M28: 1 | N28: 文字(半角のみ)
A29: S0230 | G29: S0230 | H29: ブランク | I29: S0230 | M29: 10 | N29: 文字(半角のみ)
A30: S0240 | G30: S0240 | H30: 非標準（※入出庫伝票のみ起票の前提） | I30: S0240 | M30: 55 | N30: 文字(半角のみ)
A31: S0250 | G31: S0250 | H31: ブランク | I31: S0250 | M31: 8 | N31: 文字(半角のみ)
A32: S0260 | G32: S0260 | H32: ブランク | I32: S0260 | M32: 1 | N32: 文字(半角のみ)
A33: S0270 | G33: S0270 | H33: 非標準（※入出庫伝票のみ起票の前提） | I33: S0270 | M33: 1 | N33: 文字(半角のみ)
A34: S0280 | G34: S0280 | H34: ブランク | I34: S0280 | M34: 1 | N34: 文字(半角のみ)
A35: S0290 | G35: S0290 | H35: 固定値「1」 | I35: S0290 | M35: 1 | N35: 文字(半角のみ)
A36: S0300 | G36: S0300 | H36: ブランク | I36: S0300 | M36: 1 | N36: 文字(半角のみ)
... A43: S0370 | G43: S0370 | H43: ブランク | I43: S0370 | M43: 1 | N43: 文字(半角のみ)
A44: S0380 | B44: 品目コード | C44: MATDOC | D44: MATNR | E44: 40 | F44: CHAR | G44: S0380 | I44: S0380 | J44: 検索品番 | K44: RJ071 | L44: BKSAHIN | M44: 10 | N44: 文字(半角のみ) | V44: 精确
A45: S0390 | G45: S0390 | H45: 品番を圧縮品番に変換 ロジックは「圧縮品番」参照 | I45: S0390 | M45: 4 | N45: 文字(半角のみ)
A46: S0400 | B46: 品目テキスト | C46: MAKT | D46: MAKTX | E46: 40 | F46: CHAR | G46: S0400 | I46: S0400 | J46: 品名 | K46: RJ071 | L46: NHINKN | M46: 20 | N46: 文字(半角のみ) | V46: 精确
A47: S0410 | G47: S0410 | H47: 固定値「00000」 | I47: S0410 | M47: 5 | N47: 文字(半角のみ)
...

Sheet 対象IF一覧(IDOC→FTP)
A1: IFID | M1: インターフェース名称
A2: =IF(表紙!D16<>"",表紙!D16,"") | M2: =IF(表紙!D17<>"",表紙!D17,"")
A4: 1 | B4: 代表IF基本情報
B5: ① | C5: 連携元
C6: プロトコル | H6: ALE/IDOC
C7: メッセージタイプ | N7: 基本タイプ.拡張タイプ | X7: 備考・特記事項
B10: ② | C10: 連携先
C11: プロトコル | H11: FTP
C12: ファイルフォーマット | R12: レコード長 | X12: 備考・特記事項
C13: 可変長(タブ区切り) | R13: - | X13: [フォーマットに "XML" を選択する場合] XSD File： XXXXXXXXXXXXXXXXXXXXXXXXXX.xsd （または同等の情報が得られる資料へのリンクを明記）
A15: 2 | B15: 代表IF単位での共通処理
B16: ① | C16: 実行タイミング
C17: 実行場所 | J17: 処理名 | Q17: 起動契機 | X17: 連携区分 | AE17: 再処理単位 | AL17: 備考・特記事項
C18: 連携元(部品SAP) | J18: IDOC生成 | Q18: 時間指定 | X18: 差分 | AE18: トランザクション
C19: 連携元(部品SAP) | J19: IDOC送信 | Q19: ジョブ連携 | X19: 全件 | AE19: トランザクション
C20: データ連携基盤 | J20: ETL(抽出) | Q20: 随時 | X20: 全件 | AE20: トランザクション
C21: データ連携基盤 | J21: ETL(変換) | Q21: ファイル検知 | X21: 全件 | AE21: ALL
C22: データ連携基盤 | J22: ETL(投入) | Q22: ジョブ連携 | X22: 全件 | AE22: ALL
C23: 連携先 | J23: ファイル読込 | Q23: 任意 | X23: 全件 | AE23: ALL
B26: ② | C26: ファイル操作
C27: パターン：IDOC→FTP
C28: ファイル種別 | L28: 説明 | AE28: 有無 | AG28: 複数世代 | AI28: 入出力 | AQ28: バックアップ | BC28: 削除 | BK28: リネーム：世代番号付与 | BS28: リネーム：FTP送達保証
AI29: 出力 | AM29: 入力 | AQ29: 事前(前回分) | AU29: 成功時 | AY29: 失敗時 | BC29: 成功時 | BG29: 失敗時 | BK29: 成功時 | BO29: 失敗時 | BS29: 成功時 | BW29: 失敗時
C30: 変換前ファイル | L30: 共通処理の出力、変換処理の入力ファイル。IDOC形式。 | AE30: 有 | AG30: 有 | AI30: 共通処理 | AM30: ETL(変換) | AQ30: - | AU30: ETL(変換) | AY30: - | BC30: ETL(変換) | BG30: - | BK30: 共通処理 | BO30: - | BS30: - | BW30: -
C31: 変換後ファイル | L31: 変換処理の出力、投入処理の入力ファイル。 | AE31: 有 | AG31: 有 | AI31: ETL(変換) | AM31: ETL(投入) | AQ31: - | AU31: ETL(投入) | AY31: - | BC31: ETL(投入) | BG31: - | BK31: ETL(変換) | BO31: - | BS31: - | BW31: -
C32: IFファイル(連携先) | L32: FTP連携で、データ連携基盤が連携先システムにPUTするファイル。 | AE32: 有 | AG32: 無 | AI32: ETL(投入) | AM32: 連携先 | AQ32: - | AU32: - | AY32: - | BC32: - | BG32: - | BK32: - | BO32: - | BS32: ETL(投入) | BW32: -
C33: ※ 標準と異なるファイル操作を指定したい場合のみ、AE～BZ列の内容を変更してください。標準のファイル操作については、インターフェース開発方針「4.2. 連携方式概要」を参照。
B35: ③ | C35: 順序制御
C36: ・ | D36: FIFO（受信した順番に連携する） | O36: ※FIFOではない個別の並び替え要件がある場合には、ソートのキーとなる項目および昇順/降順、複数ある場合には優先順序を明記すること。
B38: ④ | C38: トランザクション制御
C39: ・ | D39: 処理の開始時に対象となる全データを１つのトランザクションとして処理する。
A43: 3 | B43: 総IF毎の個別処理
B44: ① | C44: 連携元
C45: プロトコル | H45: ALE/IDOC
C46: No | E46: マージ版No | L46: 送信元情報 | T46: 送信先情報 | AA46: 抽出条件 | AL46: 備考・特記事項
C48: 1 | E48: 1111 | L48: ERP(S/4) | S48: ⇒ | T48: データ連携基盤 | AA48: なし
C49: 2 | E49: 2222 | L49: ERP(S/4) | S49: ⇒ | T49: データ連携基盤 | AA49: なし
C50: 3
C51: 4
C52: 5
...

Sheet 対象IF一覧(IDOC→SFTP)
A1: IFID | M1: インターフェース名称
A2: =IF(表紙!D16<>"",表紙!D16,"") | M2: =IF(表紙!D17<>"",表紙!D17,"")
A4: 1 | B4: 代表IF基本情報
B5: ① | C5: 連携元
C6: プロトコル | H6: ALE/IDOC
C7: メッセージタイプ | N7: 基本タイプ.拡張タイプ | X7: 備考・特記事項
B10: ② | C10: 連携先
C11: プロトコル | H11: SFTP
C12: ファイルフォーマット | R12: レコード長 | X12: 備考・特記事項
C13: 可変長(タブ区切り) | R13: -
A15: 2 | B15: 代表IF単位での共通処理
B16: ① | C16: 実行タイミング
C17: 実行場所 | J17: 処理名 | Q17: 起動契機 | X17: 連携区分 | AE17: 再処理単位 | AL17: 備考・特記事項
C18: 連携元(KIC) | J18: IDOC生成 | Q18: 時間指定 | X18: 差分 | AE18: トランザクション
C19: 連携元(KIC) | J19: IDOC送信 | Q19: ジョブ連携 | X19: 全件 | AE19: トランザクション
C20: データ連携基盤 | J20: ETL(抽出) | Q20: 随時 | X20: 全件 | AE20: トランザクション
C21: データ連携基盤 | J21: ETL(変換) | Q21: 時間指定 | X21: 全件 | AE21: ALL | AL21: ジョブネットは生販システムデータソースのリージョン単位で作成する。 ジョブネットは複数の変換処理を含む場合がある。
C22: データ連携基盤 | J22: ETL(投入) | Q22: ジョブ連携 | X22: 全件 | AE22: ALL | AL22: 生販システムデータソースのリージョン毎に１つだけ作成する。
C23: 連携先 | J23: ファイル読込 | Q23: 任意 | X23: 全件 | AE23: ALL
B26: ② | C26: ファイル操作
C27: パターン：IDOC→SFTP
C28: ファイル種別 | L28: 説明 | AE28: 有無 | AG28: 複数世代 | AI28: 入出力 | AQ28: バックアップ | BC28: 削除 | BK28: リネーム：世代番号付与 | BS28: リネーム：FTP送達保証
AI29: 出力 | AM29: 入力 | AQ29: 事前(前回分) | AU29: 成功時 | AY29: 失敗時 | BC29: 成功時 | BG29: 失敗時 | BK29: 成功時 | BO29: 失敗時 | BS29: 成功時 | BW29: 失敗時
C30: 変換前ファイル | L30: 共通処理の出力、変換処理の入力ファイル。IDOC形式。 | AE30: 有 | AG30: 有 | AI30: 共通処理 | AM30: ETL(変換) | AQ30: - | AU30: ETL(変換) | AY30: - | BC30: ETL(変換) | BG30: - | BK30: 共通処理 | BO30: - | BS30: - | BW30: -
C31: 変換後ファイル | L31: 変換処理の出力、投入処理の入力ファイル。 | AE31: 有 | AG31: 有 | AI31: ETL(変換) | AM31: ETL(投入) | AQ31: - | AU31: ETL(投入) | AY31: - | BC31: ETL(投入) | BG31: - | BK31: ETL(変換) | BO31: - | BS31: - | BW31: -
C32: IFファイル(連携先) | L32: データ連携基盤が連携先システムにPUTするファイル。 | AE32: 有 | AG32: 無 | AI32: ETL(投入) | AM32: 連携先 | AQ32: - | AU32: - | AY32: - | BC32: - | BG32: - | BK32: - | BO32: - | BS32: ETL(投入) | BW32: -
C33: ※ 標準と異なるファイル操作を指定したい場合のみ、AE～BZ列の内容を変更してください。標準のファイル操作については、インターフェース開発方針「4.2. 連携方式概要」を参照。
B35: ③ | C35: 順序制御
C36: ・ | D36: FIFO（受信した順番に連携する） | O36: ※FIFOではない個別の並び替え要件がある場合には、ソートのキーとなる項目および昇順/降順、複数ある場合には優先順序を明記すること。
B38: ④ | C38: トランザクション制御
C39: ・ | D39: 処理の開始時に対象となる全データを１つのトランザクションとして処理する。
A43: 3 | B43: 総IF毎の個別処理
B44: ① | C44: 連携元
C45: プロトコル | H45: ALE/IDOC
C46: No | E46: マージ版No | L46: 送信元情報 | T46: 送信先情報 | AA46: 抽出条件 | AL46: 備考・特記事項
C48: 1 | E48: 1111 | L48: ERP(S/4) | S48: ⇒ | T48: データ連携基盤 | AA48: なし
C49: 2
C50: 3
C51: 4
C52: 5
...

Sheet 対象IF一覧(FTP→IDOC)
A1: IFID | M1: インターフェース名称
A2: =IF(表紙!D16<>"",表紙!D16,"") | M2: =IF(表紙!D17<>"",表紙!D17,"")
A4: 1 | B4: 代表IF基本情報
B5: ① | C5: 連携元
C6: プロトコル | H6: FTP
C7: ファイルフォーマット | R7: レコード長 | X7: 備考・特記事項
C8: 可変長(タブ区切り) | R8: - | X8: [フォーマットに "XML" を選択する場合] XSD File： XXXXXXXXXXXXXXXXXXXXXXXXXX.xsd （または同等の情報が得られる資料へのリンクを明記）
B10: ② | C10: 連携先
C11: プロトコル | H11: ALE/IDOC
C12: メッセージタイプ | N12: 基本タイプ.拡張タイプ | X12: 備考・特記事項
A15: 2 | B15: 代表IF単位での共通処理
B16: ① | C16: 実行タイミング
C17: 実行場所 | J17: 処理名 | Q17: 起動契機 | X17: 連携区分 | AE17: 再処理単位 | AL17: 備考・特記事項
C18: 連携元 | J18: ファイル送信 | Q18: 任意 | X18: 差分 | AE18: トランザクション
C19: データ連携基盤 | J19: ETL(抽出) | Q19: ファイル検知 | X19: 全件 | AE19: トランザクション
C20: データ連携基盤 | J20: ETL(変換) | Q20: ジョブ連携 | X20: 全件 | AE20: トランザクション
C21: データ連携基盤 | J21: ETL(投入) | Q21: ジョブ連携 | X21: 全件 | AE21: トランザクション
C22: 連携先(KIC) | J22: IDOC解析 | Q22: 時間指定 | X22: 全件 | AE22: トランザクション
C23: 連携先(KIC) | J23: データ格納 | Q23: 随時 | X23: 全件 | AE23: トランザクション
B26: ② | C26: ファイル操作
C27: パターン：FTP → IDOC
C28: ファイル種別 | L28: 説明 | AE28: 有無 | AG28: 複数世代 | AI28: 入出力 | AQ28: バックアップ | BC28: 削除 | BK28: リネーム：世代番号付与 | BS28: リネーム：FTP送達保証
AI29: 出力 | AM29: 入力 | AQ29: 事前(前回分) | AU29: 成功時 | AY29: 失敗時 | BC29: 成功時 | BG29: 失敗時 | BK29: 成功時 | BO29: 失敗時 | BS29: 成功時 | BW29: 失敗時
C30: IFファイル(連携元) | L30: FTP連携で、連携元システムがデータ連携基盤にPUTしたファイル。 | AE30: 有 | AG30: 無 | AI30: 連携元 | AM30: ETL(抽出) | AQ30: - | AU30: - | AY30: - | BC30: ETL(抽出) | BG30: - | BK30: - | BO30: - | BS30: - | BW30: -
C31: 変換前ファイル | L31: 抽出処理の出力、変換処理の入力ファイル。 | AE31: 有 | AG31: 有 | AI31: ETL(抽出) | AM31: ETL(変換) | AQ31: - | AU31: ETL(変換) | AY31: - | BC31: ETL(変換) | BG31: - | BK31: ETL(抽出) | BO31: - | BS31: - | BW31: -
C32: 変換後ファイル | L32: 変換処理の出力、投入処理の入力ファイル。IDOC形式。 | AE32: 有 | AG32: 有 | AI32: ETL(変換) | AM32: ETL(投入) | AQ32: - | AU32: ETL(投入) | AY32: - | BC32: ETL(投入) | BG32: - | BK32: ETL(変換) | BO32: - | BS32: - | BW32: -
C33: ※ 標準と異なるファイル操作を指定したい場合のみ、AE～BZ列の内容を変更してください。標準のファイル操作については、インターフェース開発方針「4.2. 連携方式概要」を参照。
B35: ③ | C35: 順序制御
C36: ・ | D36: FIFO（受信した順番に連携する） | O36: ※FIFOではない個別の並び替え要件がある場合には、ソートのキーとなる項目および昇順/降順、複数ある場合には優先順序を明記すること。
B38: ④ | C38: トランザクション制御
C39: ・ | D39: IDOCの文書番号は、インタフェース対象となるファイル１件につき１つのユニークな番号を割り当てて連携を行う。
D40: ※ ERP(S/4)側の取り込み処理でコミットを発行する単位で文書番号を分けること。
A43: 3 | B43: 総IF毎の個別処理
B44: ① | C44: 連携元
C45: プロトコル | H45: FTP
C46: No | E46: マージ版No | L46: 送信元情報 | T46: 送信先情報 | AA46: 抽出条件 | AL46: ファイル名 | AV46: 保管先パス | BD46: 文字コード | BI46: 改行コード | BN46: 括り文字 | BW46: 空ファイル生成 | BZ46: ヘッダ | CC46: 備考・特記事項
C48: 1 | E48: 1111 | L48: XXXX工場 | S48: ⇒ | T48: データ連携基盤 | AA48: なし | AL48: xxx.dat | AV48: \\xxx\xxx | BD48: Shift-JIS | BI48: CR+LF | BN48: なし | BW48: 無 | BZ48: 無
C49: 2 | E49: 2222 | L49: XXXX工場 | S49: ⇒ | T49: データ連携基盤 | AA49: なし | AL49: xxx.dat | AV49: \\xxx\xxx | BD49: Shift-JIS | BI49: CR+LF | BN49: なし | BW49: 無 | BZ49: 無
C50: 3
C51: 4
...

Sheet 対象IF一覧(SFTP→IDOC)
A1: IFID | M1: インターフェース名称
A2: =IF(表紙!D16<>"",表紙!D16,"") | M2: =IF(表紙!D17<>"",表紙!D17,"")
A4: 1 | B4: 代表IF基本情報
B5: ① | C5: 連携元
C6: プロトコル | H6: SFTP
C7: ファイルフォーマット | R7: レコード長 | X7: 備考・特記事項
C8: 可変長(タブ区切り) | R8: -
B10: ② | C10: 連携先
C11: プロトコル | H11: ALE/IDOC
C12: メッセージタイプ | N12: 基本タイプ.拡張タイプ | X12: 備考・特記事項
A15: 2 | B15: 代表IF単位での共通処理
B16: ① | C16: 実行タイミング
C17: 実行場所 | J17: 処理名 | Q17: 起動契機 | X17: 連携区分 | AE17: 再処理単位 | AL17: 備考・特記事項
C18: 連携元 | J18: ファイル送信 | Q18: 任意 | X18: 差分 | AE18: トランザクション
C19: データ連携基盤 | J19: ETL(抽出) | Q19: 時間指定 | X19: 全件 | AE19: トランザクション
C20: データ連携基盤 | J20: ETL(変換) | Q20: ジョブ連携 | X20: 全件 | AE20: トランザクション
C21: データ連携基盤 | J21: ETL(投入) | Q21: ジョブ連携 | X21: 全件 | AE21: トランザクション
C22: 連携先(KIC) | J22: IDOC解析 | Q22: 時間指定 | X22: 全件 | AE22: トランザクション
C23: 連携先(KIC) | J23: データ格納 | Q23: 随時 | X23: 全件 | AE23: トランザクション
B26: ② | C26: ファイル操作
C27: パターン：SFTP → IDOC
C28: ファイル種別 | L28: 説明 | AE28: 有無 | AG28: 複数世代 | AI28: 入出力 | AQ28: バックアップ | BC28: 削除 | BK28: リネーム：世代番号付与 | BS28: リネーム：FTP送達保証
AI29: 出力 | AM29: 入力 | AQ29: 事前(前回分) | AU29: 成功時 | AY29: 失敗時 | BC29: 成功時 | BG29: 失敗時 | BK29: 成功時 | BO29: 失敗時 | BS29: 成功時 | BW29: 失敗時
C30: IFファイル(連携元) | L30: データ連携基盤が連携元システムからGETするファイル。 | AE30: 有 | AG30: 無 | AI30: 連携元 | AM30: ETL(抽出) | AQ30: - | AU30: - | AY30: - | BC30: ETL(抽出) | BG30: - | BK30: - | BO30: - | BS30: - | BW30: -
C31: 変換前ファイル | L31: 抽出処理の出力、変換処理の入力ファイル。 | AE31: 有 | AG31: 有 | AI31: ETL(抽出) | AM31: ETL(変換) | AQ31: - | AU31: ETL(変換) | AY31: - | BC31: ETL(変換) | BG31: - | BK31: ETL(抽出) | BO31: - | BS31: - | BW31: -
C32: 変換後ファイル | L32: 変換処理の出力、投入処理の入力ファイル。IDOC形式。 | AE32: 有 | AG32: 有 | AI32: ETL(変換) | AM32: ETL(投入) | AQ32: - | AU32: ETL(投入) | AY32: - | BC32: ETL(投入) | BG32: - | BK32: ETL(変換) | BO32: - | BS32: - | BW32: -
C33: ※ 標準と異なるファイル操作を指定したい場合のみ、AE～BZ列の内容を変更してください。標準のファイル操作については、インターフェース開発方針「4.2. 連携方式概要」を参照。
B35: ③ | C35: 順序制御
C36: ・ | D36: FIFO（受信した順番に連携する） | O36: ※FIFOではない個別の並び替え要件がある場合には、ソートのキーとなる項目および昇順/降順、複数ある場合には優先順序を明記すること。
B38: ④ | C38: トランザクション制御
C39: ・ | D39: IDOCの文書番号は、インタフェース対象となるファイル１件につき１つのユニークな番号を割り当てて連携を行う。
D40: ※ ERP(S/4)側の取り込み処理でコミットを発行する単位で文書番号を分けること。
A43: 3 | B43: 総IF毎の個別処理
B44: ① | C44: 連携元
C45: プロトコル | H45: SFTP
C46: No | E46: マージ版No | L46: 送信元情報 | T46: 送信先情報 | AA46: 抽出条件 | AL46: ファイル名 | AV46: 保管先パス | BD46: 文字コード | BI46: 改行コード | BN46: 括り文字 | BW46: 空ファイル生成 | BZ46: ヘッダ | CC46: 備考・特記事項
C48: 1 | E48: 1111 | L48: 生販システム | S48: ⇒ | T48: データ連携基盤 | AA48: なし | AL48: xxx.dat | AV48: Outbound/ | BD48: UTF-8 | BI48: CR+LF | BN48: なし | BW48: 無 | BZ48: 無
C49: 2
B51: ② | C51: 連携先
C52: プロトコル | H52: ALE/IDOC
...

Sheet 対象IF一覧(MQ→FTP)
A1: IFID | M1: インターフェース名称
A2: =IF(表紙!D16<>"",表紙!D16,"") | M2: =IF(表紙!D17<>"",表紙!D17,"")
A4: 1 | B4: 代表IF基本情報
B5: ① | C5: 連携元
C6: プロトコル | H6: MSMQ
C7: メッセージフォーマット | R7: レコード長 | X7: 備考・特記事項
C8: XML | R8: ー | X8: [フォーマットに "XML" を選択する場合] XSD File： XXXXXXXXXXXXXXXXXXXXXXXXXX.xsd （または同等の情報が得られる資料へのリンクを明記）
B10: ② | C10: 連携先
C11: プロトコル | H11: FTP
C12: ファイルフォーマット | R12: レコード長 | X12: 備考・特記事項
C13: 可変長(タブ区切り) | R13: - | X13: [フォーマットに "XML" を選択する場合] XSD File： XXXXXXXXXXXXXXXXXXXXXXXXXX.xsd （または同等の情報が得られる資料へのリンクを明記）
A15: 2 | B15: 代表IF単位での共通処理
B16: ① | C16: 実行タイミング
C17: 実行場所 | J17: 処理名 | Q17: 起動契機 | X17: 連携区分 | AE17: 再処理単位 | AL17: 備考・特記事項
C18: 連携元 | J18: メッセージ送信 | Q18: 任意 | X18: 差分 | AE18: トランザクション
C19: データ連携基盤 | J19: ETL(抽出) | Q19: 随時 | X19: 全件 | AE19: トランザクション
C20: データ連携基盤 | J20: ETL(変換) | Q20: 時間指定 | X20: 全件 | AE20: ALL
C21: データ連携基盤 | J21: ETL(投入) | Q21: ジョブ連携 | X21: 全件 | AE21: ALL
C22: 連携先 | J22: ファイル読込 | Q22: 任意 | X22: 全件 | AE22: ALL
B26: ② | C26: ファイル操作
C27: パターン：MQ → FTP
C28: ファイル種別 | L28: 説明 | AE28: 有無 | AG28: 複数世代 | AI28: 入出力 | AQ28: バックアップ | BC28: 削除 | BK28: リネーム：世代番号付与 | BS28: リネーム：FTP送達保証
AI29: 出力 | AM29: 入力 | AQ29: 事前(前回分) | AU29: 成功時 | AY29: 失敗時 | BC29: 成功時 | BG29: 失敗時 | BK29: 成功時 | BO29: 失敗時 | BS29: 成功時 | BW29: 失敗時
C30: MQメッセージ(連携元) | L30: 連携元がデータ連携基盤向けのリモートキューにPUTしたメッセージ。 | AE30: 有 | AG30: 有 | AI30: 連携元 | AM30: ETL(抽出) | AQ30: - | AU30: - | AY30: - | BC30: ETL(抽出) | BG30: - | BK30: - | BO30: - | BS30: - | BW30: -
C31: 変換前ファイル | L31: 抽出処理の出力、変換処理の入力ファイル。 | AE31: 有 | AG31: 有 | AI31: ETL(抽出) | AM31: ETL(変換) | AQ31: - | AU31: ETL(変換) | AY31: - | BC31: ETL(変換) | BG31: - | BK31: ETL(抽出) | BO31: - | BS31: - | BW31: -
C32: 変換後ファイル | L32: 変換処理の出力、投入処理の入力ファイル。IDOC形式。 | AE32: 有 | AG32: 有 | AI32: ETL(変換) | AM32: ETL(投入) | AQ32: - | AU32: ETL(投入) | AY32: - | BC32: ETL(投入) | BG32: - | BK32: ETL(変換) | BO32: - | BS32: - | BW32: -
C33: ※ 標準と異なるファイル操作を指定したい場合のみ、AE～BZ列の内容を変更してください。標準のファイル操作については、インターフェース開発方針「4.2. 連携方式概要」を参照。
B35: ③ | C35: 順序制御
C36: ・ | D36: FIFO（受信した順番に連携する） | O36: ※FIFOではない個別の並び替え要件がある場合には、ソートのキーとなる項目および昇順/降順、複数ある場合には優先順序を明記すること。
B38: ④ | C38: トランザクション制御
C39: ・ | D39: 処理の開始時に対象となる全データを１つのトランザクション(ファイル)として処理する。
A43: 3 | B43: 総IF毎の個別処理
B44: ① | C44: 連携元
C45: プロトコル | H45: MSMQ
C46: No | E46: マージ版No | L46: 送信元情報 | T46: 送信先情報 | AA46: キュー名 | AG46: ラベル | AM46: 抽出条件 | AX46: 文字コード | BC46: トランザクション | BH46: ジャーナル | BM46: 記憶域の最大サイズ | BU46: 認証 | BW46: 0件時 送信 | BZ46: 備考・特記事項
BM47: メッセージ | BQ47: ジャーナル
C48: 1 | E48: 1000 | L48: Apriso MES(堺) | S48: ⇒ | T48: データ連携基盤 | AA48: KIC.MES.Queue.01 | AM48: なし | AX48: UTF-8 | BC48: 無効 | BH48: 無効 | BM48: 初期値 | BQ48: 初期値 | BU48: 無 | BW48: 無
C49: 2 | E49: 2000 | L49: Apriso MES(臨海) | S49: ⇒ | T49: データ連携基盤 | AA49: KIC.MES.Queue.02 | AM49: なし | AX49: UTF-8 | BC49: 無効 | BH49: 無効 | BM49: 初期値 | BQ49: 初期値 | BU49: 無 | BW49: 無
C50: 3 | E50: 3000 | L50: Apriso MES(筑波) | S50: ⇒ | T50: データ連携基盤 | AA50: KIC.MES.Queue.03 | AM50: なし | AX50: UTF-8 | BC50: 無効 | BH50: 無効 | BM50: 初期値 | BQ50: 初期値 | BU50: 無 | BW50: 無
C51: 4 | E51: 4000 | L51: Apriso MES(宇都宮) | S51: ⇒ | T51: データ連携基盤 | AA51: KIC.MES.Queue.04 | AM51: なし | AX51: UTF-8 | BC51: 無効 | BH51: 無効 | BM51: 初期値 | BQ51: 初期値 | BU51: 無 | BW51: 無
...

Sheet 対象IF一覧(FTP→MQ)
A1: IFID | M1: インターフェース名称
A2: =IF(表紙!D16<>"",表紙!D16,"") | M2: =IF(表紙!D17<>"",表紙!D17,"")
A4: 1 | B4: 代表IF基本情報
B5: ① | C5: 連携元
C6: プロトコル | H6: FTP
C7: ファイルフォーマット | R7: レコード長 | X7: 備考・特記事項
C8: 可変長(タブ区切り) | R8: - | X8: [フォーマットに "XML" を選択する場合] XSD File： XXXXXXXXXXXXXXXXXXXXXXXXXX.xsd （または同等の情報が得られる資料へのリンクを明記）
B10: ② | C10: 連携先
C11: プロトコル | H11: MSMQ
C12: メッセージフォーマット | R12: レコード長 | X12: 備考・特記事項
C13: XML | R13: ー | X13: [フォーマットに "XML" を選択する場合] XSD File： XXXXXXXXXXXXXXXXXXXXXXXXXX.xsd （または同等の情報が得られる資料へのリンクを明記）
A15: 2 | B15: 代表IF単位での共通処理
B16: ① | C16: 実行タイミング
C17: 実行場所 | J17: 処理名 | Q17: 起動契機 | X17: 連携区分 | AE17: 再処理単位 | AL17: 備考・特記事項
C18: 連携元 | J18: ファイル送信 | Q18: 任意 | X18: 差分 | AE18: トランザクション
C19: データ連携基盤 | J19: ETL(抽出) | Q19: 時間指定 | X19: 全件 | AE19: トランザクション
C20: データ連携基盤 | J20: ETL(変換) | Q20: ジョブ連携 | X20: 全件 | AE20: トランザクション
C21: データ連携基盤 | J21: ETL(投入) | Q21: ジョブ連携 | X21: 全件 | AE21: トランザクション
C22: 連携先 | J22: メッセージ取得 | Q22: 任意 | X22: 全件 | AE22: トランザクション
B26: ② | C26: ファイル操作
C27: パターン：FTP → MQ
C28: ファイル種別 | L28: 説明 | AE28: 有無 | AG28: 複数世代 | AI28: 入出力 | AQ28: バックアップ | BC28: 削除 | BK28: リネーム：世代番号付与 | BS28: リネーム：FTP送達保証
AI29: 出力 | AM29: 入力 | AQ29: 事前(前回分) | AU29: 成功時 | AY29: 失敗時 | BC29: 成功時 | BG29: 失敗時 | BK29: 成功時 | BO29: 失敗時 | BS29: 成功時 | BW29: 失敗時
C30: 変換前ファイル | L30: 共通処理の出力、変換処理の入力ファイル。IDOC形式。 | AE30: 有 | AG30: 有 | AI30: 共通処理 | AM30: ETL(変換) | AQ30: - | AU30: ETL(変換) | AY30: - | BC30: ETL(変換) | BG30: - | BK30: 共通処理 | BO30: - | BS30: - | BW30: -
C31: 変換後ファイル | L31: 変換処理の出力、投入処理の入力ファイル。 | AE31: 有 | AG31: 有 | AI31: ETL(変換) | AM31: ETL(投入) | AQ31: - | AU31: ETL(投入) | AY31: - | BC31: ETL(投入) | BG31: - | BK31: ETL(変換) | BO31: - | BS31: - | BW31: -
C32: MQメッセージ(連携先) | L32: データ連携基盤が連携先向けのリモートキューにPUTしたメッセージ。 | AE32: 有 | AG32: 有 | AI32: ETL(投入) | AM32: 連携先 | AQ32: - | AU32: - | AY32: - | BC32: - | BG32: - | BK32: - | BO32: - | BS32: - | BW32: -
C33: ※ 標準と異なるファイル操作を指定したい場合のみ、AE～BZ列の内容を変更してください。標準のファイル操作については、インターフェース開発方針「4.2. 連携方式概要」を参照。
B35: ③ | C35: 順序制御
C36: ・ | D36: FIFO（受信した順番に連携する） | O36: ※FIFOではない個別の並び替え要件がある場合には、ソートのキーとなる項目および昇順/降順、複数ある場合には優先順序を明記すること。
B38: ④ | C38: トランザクション制御
C39: ・ | D39: 処理の開始時に対象となる全データを１つのトランザクションとして処理する。
A43: 3 | B43: 総IF毎の個別処理
B44: ① | C44: 連携元
C45: プロトコル | H45: FTP
C46: No | E46: マージ版No | L46: 送信元情報 | T46: 送信先情報 | AA46: 抽出条件 | AL46: ファイル名 | AV46: 保管先パス | BD46: 文字コード | BI46: 改行コード | BN46: 括り文字 | BW46: 空ファイル生成 | BZ46: ヘッダ | CC46: 備考・特記事項
C48: 1 | E48: 1000 | L48: 堺工場 | S48: ⇒ | T48: データ連携基盤 | AA48: なし | AL48: xxx.dat | AV48: \\xxx\xxx | BD48: Shift-JIS | BI48: CR+LF | BN48: なし | BW48: 無 | BZ48: 無
C49: 2 | E49: 2000 | L49: 臨海工場 | S49: ⇒ | T49: データ連携基盤 | AA49: なし | AL49: xxx.dat | AV49: \\xxx\xxx | BD49: Shift-JIS | BI49: CR+LF | BN49: なし | BW49: 無 | BZ49: 無
C50: 3 | E50: 3000 | L50: 筑波工場 | S50: ⇒ | T50: データ連携基盤 | AA50: なし | AL50: xxx.dat | AV50: \\xxx\xxx | BD50: Shift-JIS | BI50: CR+LF | BN50: なし | BW50: 無 | BZ50: 無
C51: 4 | E51: 4000 | L51: 宇都宮工場 | S51: ⇒ | T51: データ連携基盤 | AA51: なし | AL51: xxx.dat | AV51: \\xxx\xxx | BD51: Shift-JIS | BI51: CR+LF | BN51: なし | BW51: 無 | BZ51: 無
C52: 5 | E52: 5000 | L52: 枚方工場 | S52: ⇒ | T52: データ連携基盤 | AA52: なし | AL52: xxx.dat | AV52: \\xxx\xxx | BD52: Shift-JIS | BI52: CR+LF | BN52: なし | BW52: 無 | BZ52: 無
...

Sheet 対象IF一覧(SFTP→FTP)
A1: IFID | M1: インターフェース名称
A2: =IF(表紙!D16<>"",表紙!D16,"") | M2: =IF(表紙!D17<>"",表紙!D17,"")
A4: 1 | B4: 代表IF基本情報
B5: ① | C5: 連携元
C6: プロトコル | H6: SFTP
C7: ファイルフォーマット | R7: レコード長 | X7: 備考・特記事項
C8: 可変長(タブ区切り) | R8: -
B10: ② | C10: 連携先
C11: プロトコル | H11: FTP
C12: ファイルフォーマット | R12: レコード長 | X12: 備考・特記事項
C13: 可変長(タブ区切り) | R13: - | X13: [フォーマットに "XML" を選択する場合] XSD File： XXXXXXXXXXXXXXXXXXXXXXXXXX.xsd （または同等の情報が得られる資料へのリンクを明記）
A15: 2 | B15: 代表IF単位での共通処理
B16: ① | C16: 実行タイミング
C17: 実行場所 | J17: 処理名 | Q17: 起動契機 | X17: 連携区分 | AE17: 再処理単位 | AL17: 備考・特記事項
C18: 連携元 | J18: ファイル送信 | Q18: 任意 | X18: 差分 | AE18: トランザクション
C19: データ連携基盤 | J19: ETL(抽出) | Q19: 時間指定 | X19: 全件 | AE19: トランザクション
C20: データ連携基盤 | J20: ETL(変換) | Q20: ジョブ連携 | X20: 全件 | AE20: ALL
C21: データ連携基盤 | J21: ETL(投入) | Q21: ジョブ連携 | X21: 全件 | AE21: ALL
C22: 連携先 | J22: ファイル読込 | Q22: 任意 | X22: 全件 | AE22: ALL
B26: ② | C26: ファイル操作
C27: パターン：SFTP → IDOC
C28: ファイル種別 | L28: 説明 | AE28: 有無 | AG28: 複数世代 | AI28: 入出力 | AQ28: バックアップ | BC28: 削除 | BK28: リネーム：世代番号付与 | BS28: リネーム：FTP送達保証
AI29: 出力 | AM29: 入力 | AQ29: 事前(前回分) | AU29: 成功時 | AY29: 失敗時 | BC29: 成功時 | BG29: 失敗時 | BK29: 成功時 | BO29: 失敗時 | BS29: 成功時 | BW29: 失敗時
C30: IFファイル(連携元) | L30: データ連携基盤が連携元システムからGETするファイル。 | AE30: 有 | AG30: 無 | AI30: 連携元 | AM30: ETL(抽出) | AQ30: - | AU30: - | AY30: - | BC30: ETL(抽出) | BG30: - | BK30: - | BO30: - | BS30: - | BW30: -
C31: 変換前ファイル | L31: 抽出処理の出力、変換処理の入力ファイル。 | AE31: 有 | AG31: 有 | AI31: ETL(抽出) | AM31: ETL(変換) | AQ31: - | AU31: ETL(変換) | AY31: - | BC31: ETL(変換) | BG31: - | BK31: ETL(抽出) | BO31: - | BS31: - | BW31: -
C32: 変換後ファイル | L32: 変換処理の出力、投入処理の入力ファイル。 | AE32: 有 | AG32: 有 | AI32: ETL(変換) | AM32: ETL(投入) | AQ32: - | AU32: ETL(投入) | AY32: - | BC32: ETL(投入) | BG32: - | BK32: ETL(変換) | BO32: - | BS32: - | BW32: -
C33: IFファイル(連携先) | L33: FTP連携で、データ連携基盤が連携先システムにPUTするファイル。 | AE33: 有 | AG33: 無 | AI33: ETL(投入) | AM33: 連携先 | AQ33: - | AU33: - | AY33: - | BC33: - | BG33: - | BK33: - | BO33: - | BS33: ETL(投入) | BW33: -
C34: ※ 標準と異なるファイル操作を指定したい場合のみ、AE～BZ列の内容を変更してください。標準のファイル操作については、インターフェース開発方針「4.2. 連携方式概要」を参照。
B36: ③ | C36: 順序制御
C37: ・ | D37: FIFO（受信した順番に連携する） | O37: ※FIFOではない個別の並び替え要件がある場合には、ソートのキーとなる項目および昇順/降順、複数ある場合には優先順序を明記すること。
B39: ④ | C39: トランザクション制御
C40: ・ | D40: 処理の開始時に対象となる全データを１つのトランザクションとして処理する。
A44: 3 | B44: 総IF毎の個別処理
B45: ① | C45: 連携元
C46: プロトコル | H46: SFTP
C47: No | E47: マージ版No | L47: 送信元情報 | T47: 送信先情報 | AA47: 抽出条件 | AL47: ファイル名 | AV47: 保管先パス | BD47: 文字コード | BI47: 改行コード | BN47: 括り文字 | BW47: 空ファイル生成 | BZ47: ヘッダ | CC47: 備考・特記事項
C49: 1 | E49: 9999 | L49: 生販システム | S49: ⇒ | T49: データ連携基盤 | AA49: なし | AL49: xxx.dat | AV49: Outbound/ | BD49: UTF-8 | BI49: CR+LF | BN49: なし | BW49: 無 | BZ49: 無
C50: 2
C51: 3
C52: 4
...

Sheet 対象IF一覧(FTP→SFTP)
A1: IFID | M1: インターフェース名称
A2: =IF(表紙!D16<>"",表紙!D16,"") | M2: =IF(表紙!D17<>"",表紙!D17,"")
A4: 1 | B4: 代表IF基本情報
B5: ① | C5: 連携元
C6: プロトコル | H6: FTP
C7: ファイルフォーマット | R7: レコード長 | X7: 備考・特記事項
C8: 可変長(タブ区切り) | R8: - | X8: [フォーマットに "XML" を選択する場合] XSD File： XXXXXXXXXXXXXXXXXXXXXXXXXX.xsd （または同等の情報が得られる資料へのリンクを明記）
B10: ② | C10: 連携先
C11: プロトコル | H11: SFTP
C12: ファイルフォーマット | R12: レコード長 | X12: 備考・特記事項
C13: 可変長(タブ区切り) | R13: -
A15: 2 | B15: 代表IF単位での共通処理
B16: ① | C16: 実行タイミング
C17: 実行場所 | J17: 処理名 | Q17: 起動契機 | X17: 連携区分 | AE17: 再処理単位 | AL17: 備考・特記事項
C18: 連携元 | J18: ファイル送信 | Q18: 任意 | X18: 差分 | AE18: トランザクション
C19: データ連携基盤 | J19: ETL(抽出) | Q19: 時間指定 | X19: 全件 | AE19: トランザクション | AL19: 対象ファイルの到着を待つ。
C20: データ連携基盤 | J20: ETL(変換) | Q20: ジョブ連携 | X20: 全件 | AE20: ALL | AL20: ジョブネットは生販システムデータソースのリージョン単位で作成する。 ジョブネットは複数の変換処理を含む場合がある。
C21: データ連携基盤 | J21: ETL(投入) | Q21: ジョブ連携 | X21: 全件 | AE21: ALL | AL21: 生販システムデータソースのリージョン毎に１つだけ作成する。
C22: 連携先 | J22: ファイル読込 | Q22: 任意 | X22: 全件 | AE22: ALL
B26: ② | C26: ファイル操作
C27: パターン：FTP → SFTP
C28: ファイル種別 | L28: 説明 | AE28: 有無 | AG28: 複数世代 | AI28: 入出力 | AQ28: バックアップ | BC28: 削除 | BK28: リネーム：世代番号付与 | BS28: リネーム：FTP送達保証
AI29: 出力 | AM29: 入力 | AQ29: 事前(前回分) | AU29: 成功時 | AY29: 失敗時 | BC29: 成功時 | BG29: 失敗時 | BK29: 成功時 | BO29: 失敗時 | BS29: 成功時 | BW29: 失敗時
C30: IFファイル(連携元) | L30: FTP連携で、連携元システムがデータ連携基盤にPUTしたファイル。 | AE30: 有 | AG30: 無 | AI30: 連携元 | AM30: ETL(抽出) | AQ30: - | AU30: - | AY30: - | BC30: ETL(抽出) | BG30: - | BK30: - | BO30: - | BS30: - | BW30: -
C31: 変換前ファイル | L31: 抽出処理の出力、変換処理の入力ファイル。 | AE31: 有 | AG31: 有 | AI31: ETL(抽出) | AM31: ETL(変換) | AQ31: - | AU31: ETL(変換) | AY31: - | BC31: ETL(変換) | BG31: - | BK31: ETL(抽出) | BO31: - | BS31: - | BW31: -
C32: 変換後ファイル | L32: 変換処理の出力、投入処理の入力ファイル。 | AE32: 有 | AG32: 有 | AI32: ETL(変換) | AM32: ETL(投入) | AQ32: - | AU32: ETL(投入) | AY32: - | BC32: ETL(投入) | BG32: - | BK32: ETL(変換) | BO32: - | BS32: - | BW32: -
C33: IFファイル(連携先) | L33: データ連携基盤が連携先システムにPUTするファイル。 | AE33: 有 | AG33: 無 | AI33: ETL(投入) | AM33: 連携先 | AQ33: - | AU33: - | AY33: - | BC33: - | BG33: - | BK33: - | BO33: - | BS33: ETL(投入) | BW33: -
C34: ※ 標準と異なるファイル操作を指定したい場合のみ、AE～BZ列の内容を変更してください。標準のファイル操作については、インターフェース開発方針「4.2. 連携方式概要」を参照。
B36: ③ | C36: 順序制御
C37: ・ | D37: FIFO（受信した順番に連携する） | O37: ※FIFOではない個別の並び替え要件がある場合には、ソートのキーとなる項目および昇順/降順、複数ある場合には優先順序を明記すること。
B39: ④ | C39: トランザクション制御
C40: ・ | D40: 処理の開始時に対象となる全データを１つのトランザクションとして処理する。
A44: 3 | B44: 総IF毎の個別処理
B45: ① | C45: 連携元
C46: プロトコル | H46: FTP
C47: No | E47: マージ版No | L47: 送信元情報 | T47: 送信先情報 | AA47: 抽出条件 | AL47: ファイル名 | AV47: 保管先パス | BD47: 文字コード | BI47: 改行コード | BN47: 括り文字 | BW47: 空ファイル生成 | BZ47: ヘッダ | CC47: 備考・特記事項
C49: 1 | E49: 1111 | L49: XXXX工場 | S49: ⇒ | T49: データ連携基盤 | AA49: なし | AL49: xxx.dat | AV49: \\xxx\xxx | BD49: Shift-JIS | BI49: CR+LF | BN49: なし | BW49: 無 | BZ49: 無
C50: 2
C51: 3
C52: 4
...

Sheet 対象IF一覧(FTP→FTP)
A1: IFID | M1: インターフェース名称
A2: =IF(表紙!D16<>"",表紙!D16,"") | M2: =IF(表紙!D17<>"",表紙!D17,"")
A4: 1 | B4: 代表IF基本情報
B5: ① | C5: 連携元
C6: プロトコル | H6: FTP
C7: ファイルフォーマット | R7: レコード長 | X7: 備考・特記事項
C8: 可変長(タブ区切り) | R8: -
B10: ② | C10: 連携先
C11: プロトコル | H11: FTP
C12: ファイルフォーマット | R12: レコード長 | X12: 備考・特記事項
C13: 可変長(タブ区切り) | R13: -
A15: 2 | B15: 代表IF単位での共通処理
B16: ① | C16: 実行タイミング
C17: 実行場所 | J17: 処理名 | Q17: 起動契機 | X17: 連携区分 | AE17: 再処理単位 | AL17: 備考・特記事項
C18: 連携元 | J18: ファイル送信 | Q18: 任意 | X18: 差分 | AE18: トランザクション
C19: データ連携基盤 | J19: ETL(抽出) | Q19: 時間指定 | X19: 全件 | AE19: トランザクション
C20: データ連携基盤 | J20: ETL(変換) | Q20: ジョブ連携 | X20: 全件 | AE20: トランザクション
C21: データ連携基盤 | J21: ETL(投入) | Q21: ジョブ連携 | X21: 全件 | AE21: トランザクション
B24: ② | C24: ファイル操作
C25: パターン：FTP → FTP
C26: ファイル種別 | L26: 説明 | AE26: 有無 | AG26: 複数世代 | AI26: 入出力 | AQ26: バックアップ | BC26: 削除 | BK26: リネーム：世代番号付与 | BS26: リネーム：FTP送達保証
AI27: 出力 | AM27: 入力 | AQ27: 事前(前回分) | AU27: 成功時 | AY27: 失敗時 | BC27: 成功時 | BG27: 失敗時 | BK27: 成功時 | BO27: 失敗時 | BS27: 成功時 | BW27: 失敗時
C28: IFファイル(連携元) | L28: FTP連携で、連携元システムがデータ連携基盤にPUTしたファイル。 | AE28: 有 | AG28: 無 | AI28: 連携元 | AM28: ETL(抽出) | AQ28: - | AU28: - | AY28: - | BC28: ETL(抽出) | BG28: - | BK28: - | BO28: - | BS28: - | BW28: -
C29: 変換前ファイル | L29: 抽出処理の出力、変換処理の入力ファイル。 | AE29: 有 | AG29: 有 | AI29: ETL(抽出) | AM29: ETL(変換) | AQ29: - | AU29: ETL(変換) | AY29: - | BC29: ETL(変換) | BG29: - | BK29: ETL(抽出) | BO29: - | BS29: - | BW29: -
C30: 変換後ファイル | L30: 変換処理の出力、投入処理の入力ファイル。 | AE30: 有 | AG30: 有 | AI30: ETL(変換) | AM30: ETL(投入) | AQ30: - | AU30: ETL(投入) | AY30: - | BC30: ETL(投入) | BG30: - | BK30: ETL(変換) | BO30: - | BS30: - | BW30: -
C31: IFファイル(連携先) | L31: FTP連携で、データ連携基盤が連携先システムにPUTするファイル。 | AE31: 有 | AG31: 無 | AI31: ETL(投入) | AM31: 連携先 | AQ31: - | AU31: - | AY31: - | BC31: - | BG31: - | BK31: - | BO31: - | BS31: ETL(投入) | BW31: -
C32: ※ 標準と異なるファイル操作を指定したい場合のみ、AE～BZ列の内容を変更してください。標準のファイル操作については、インターフェース開発方針「4.2. 連携方式概要」を参照。
B34: ③ | C34: 順序制御
C35: ・ | D35: FIFO（受信した順番に連携する） | O35: ※FIFOではない個別の並び替え要件がある場合には、ソートのキーとなる項目および昇順/降順、複数ある場合には優先順序を明記すること。
B37: ④ | C37: トランザクション制御
C38: ・ | D38: 処理の開始時に対象となる全データを１つのトランザクションとして処理する。
A42: 3 | B42: 総IF毎の個別処理
B43: ① | C43: 連携元
C44: プロトコル | H44: FTP
C45: No | E45: マージ版No | L45: 送信元情報 | T45: 送信先情報 | AA45: 抽出条件 | AL45: ファイル名 | AV45: 保管先パス | BD45: 文字コード | BI45: 改行コード | BN45: 括り文字 | BW45: 空ファイル生成 | BZ45: ヘッダ | CC45: 備考・特記事項
C47: 1 | E47: 9999 | L47: 北米ERP(S/4) | S47: ⇒ | T47: データ連携基盤 | AA47: なし | AV47: $home/inrecv/ | BD47: UTF-8 | BI47: CR+LF | BN47: なし | BW47: 無 | BZ47: 無
C48: 2
C49: 3
C50: 4
C51: 5
...

Sheet 対象IF一覧(BAPI)
A1: IFID | M1: インターフェース名称
A2: =IF(表紙!D16<>"",表紙!D16,"") | M2: =IF(表紙!D17<>"",表紙!D17,"")
A4: 1 | B4: 代表IF基本情報
B5: ① | C5: 連携元
C6: クライアントプログラム名 | X6: 備考・特記事項
B9: ② | C9: 連携先
C10: プロトコル | H10: RFC/BAPI
C11: RFC/BAPI名 | R11: 操作内容 | X11: 備考・特記事項
C12: BAPI_USER_GET_DETAIL | R12: 取得
A14: 2 | B14: 代表IF単位での共通処理
B15: ① | C15: 実行タイミング
C16: 実行場所 | J16: 処理名 | Q16: 起動契機 | X16: 連携区分 | AE16: 再処理単位 | AL16: 備考・特記事項
C17: 連携元(KIC) | J17: BAPI呼出 | Q17: 随時 | AE17: トランザクション
C18: 連携先(KIC) | J18: RFC/BAPI実行 | Q18: 随時 | X18: 差分 | AE18: トランザクション
B21: ② | C21: ファイル操作
C22: ・ | D22: なし
B24: ③ | C24: 順序制御
C25: ・ | D25: なし
B27: ④ | C27: トランザクション制御
C28: ・ | D28: １件のリクエストを１つのトランザクションとして処理する。
A32: 3 | B32: 総IF毎の個別処理
C34: プロトコル | H34: RFC/BAPI
C35: No | E35: マージ版No | L35: 送信元情報 | T35: 送信先情報 | AA35: コミット発行 | AH35: コミット完了待機 | AO35: コミット間隔 | AV35: 備考・特記事項
C37: 1 | E37: 9901 | L37: 調達ポータル | S37: ⇔ | T37: ERP(S/4) | AA37: 無 | AH37: 有 | AO37: なし
C38: 2
C39: 3
C40: 4
C41: 5
A43: 4 | B43: システムフロー（任意記載）
B57: ※ | C57: 直接連携（BAPI呼出）のインタフェースパターンでは、シート [項目マッピング][PWC設計] は不要。
B58: ※ | C58: 連携元/連携先側の処理については、「1.代表IF基本情報」欄に記載のPGMに対する基本設計書を参照。それ以外に参照すべきドキュメントがある場合は、以下に記載。

Sheet 対象IF一覧(SOAP→BAPI)
A1: IFID | M1: インターフェース名称
A2: =IF(表紙!D16<>"",表紙!D16,"") | M2: =IF(表紙!D17<>"",表紙!D17,"")
A4: 1 | B4: 代表IF基本情報
B5: ① | C5: 連携元
C6: クライアントプログラム名 | X6: 備考・特記事項
B9: ② | C9: ETL
C10: プロトコル | H10: SOAP
C11: WEBサービス名 | R11: 認証による保護 | X11: 備考・特記事項
C12: 《IFID》_WEB_《マージ版No》 | R12: 無
B14: ③ | C14: 連携先
C15: プロトコル | H15: RFC/BAPI
C16: RFC/BAPI名 | R16: 操作内容 | X16: 備考・特記事項
C17: BAPI_USER_GET_DETAIL | R17: 取得
A19: 2 | B19: 代表IF単位での共通処理
B20: ① | C20: 実行タイミング
C21: 実行場所 | J21: 処理名 | Q21: 起動契機 | X21: 連携区分 | AE21: 再処理単位 | AL21: 備考・特記事項
C22: 連携元 | J22: SOAP呼出 | Q22: 随時 | X22: 差分 | AE22: トランザクション
C23: データ連携基盤 | J23: ETL(WEB) | Q23: 随時 | X23: 全件 | AE23: トランザクション
C24: 連携先(KIC) | J24: RFC/BAPI実行 | Q24: 随時 | X24: 全件 | AE24: トランザクション
B26: ② | C26: ファイル操作
C27: ・ | D27: なし
B29: ③ | C29: 順序制御
C30: ・ | D30: なし
B32: ④ | C32: トランザクション制御
C33: ・ | D33: １件のリクエストを１つのトランザクションとして処理する。
A37: 3 | B37: 総IF毎の個別処理
B38: ① | C38: 連携元
C39: プロトコル | H39: SOAP
C40: No | E40: マージ版No | L40: 送信元情報 | T40: 送信先情報 | AA40: タイムアウト (秒) | AH40: アイドル時間 (秒) | AO40: 備考・特記事項
C42: 1 | E42: 8029 | L42: 堺工場 | S42: ⇔ | T42: データ連携基盤 | AA42: 60 | AH42: 180
C43: 2 | E43: 8480 | L43: 枚方工場 | S43: ⇔ | T43: データ連携基盤 | AA43: 60 | AH43: 180
C44: 3
C45: 4
C46: 5
B48: ② | C48: 連携先
C49: プロトコル | H49: RFC/BAPI
C50: No | E50: マージ版No | L50: 送信元情報 | T50: 送信先情報 | AA50: コミット発行 | AH50: コミット完了待機 | AO50: コミット間隔 | AV50: 備考・特記事項
C52: 1 | E52: 8029 | L52: データ連携基盤 | S52: ⇔ | T52: ERP(S/4) | AA52: 無 | AH52: 有 | AO52: 1000
C53: 2 | E53: 8480 | L53: データ連携基盤 | S53: ⇔ | T53: ERP(S/4) | AA53: 無 | AH53: 有 | AO53: 1000
C54: 3
...

Sheet 対象IF一覧(IDOC→SOAP)
A1: IFID | M1: インターフェース名称
A2: =IF(表紙!D16<>"",表紙!D16,"") | M2: =IF(表紙!D17<>"",表紙!D17,"")
A4: 1 | B4: 代表IF基本情報
B5: ① | C5: 連携元
C6: プロトコル | H6: ALE/IDOC
C7: メッセージタイプ | N7: 基本タイプ.拡張タイプ | X7: 備考・特記事項
X8: SOAP呼出で取得したい値はブランクの状態でインタフェースする。 ブランク項目にSOAP呼出で取得した値を詰めて、同じメッセージタイプ/基本タイプのIDOCをSAPへ送り返す。 汎用検索Webサービスが返却する E生販システムorCode / E生販システムorMessage を格納する項目もブランクの状態でインタフェースする。
B10: ② | C10: 連携先
C11: プロトコル | H11: SOAP
C12: WEBサービス名 | R12: 認証による保護 | X12: 備考・特記事項
C13: ws_General-PurposeSearch | R13: 有 | X13: WebサービスURL： https://xxxxxxxxxxxxxxxxxxxxxxxxxxxxxxxxxxxxxx ライセンス情報、VIEW名、データ検索条件、項目名をパラメータに、条件に合致する値を検索する。APIに引渡すパラメータの詳細についてはシート[PWC設計]を参照。
A16: 2 | B16: 代表IF単位での共通処理
B17: ① | C17: 実行タイミング
C18: 実行場所 | J18: 処理名 | Q18: 起動契機 | X18: 連携区分 | AE18: 再処理単位 | AL18: 備考・特記事項
C19: 連携元(KIC) | J19: IDOC生成 | Q19: 時間指定 | X19: 差分 | AE19: トランザクション
C20: 連携元(KIC) | J20: IDOC送信 | Q20: ジョブ連携 | X20: 全件 | AE20: トランザクション
C21: データ連携基盤 | J21: ETL(抽出) | Q21: 随時 | X21: 全件 | AE21: トランザクション
C22: データ連携基盤 | J22: ETL(変換) | Q22: ファイル検知 | X22: 全件 | AE22: ALL | AL22: 汎用検索WebサービスのSOAP呼出を実行。
C23: データ連携基盤 | J23: ETL(投入) | Q23: ジョブ連携 | X23: 全件 | AE23: ALL
C24: 連携先(KIC) | J24: IDOC解析 | Q24: 時間指定 | X24: 全件 | AE24: トランザクション
C25: 連携先(KIC) | J25: データ格納 | Q25: 随時 | X25: 全件 | AE25: トランザクション
B28: ② | C28: ファイル操作
C29: パターン：IDOC ⇔ SOAP
C30: ファイル種別 | L30: 説明 | AE30: 有無 | AG30: 複数世代 | AI30: 入出力 | AQ30: バックアップ | BC30: 削除 | BK30: リネーム：世代番号付与 | BS30: リネーム：FTP送達保証
AI31: 出力 | AM31: 入力 | AQ31: 事前(前回分) | AU31: 成功時 | AY31: 失敗時 | BC31: 成功時 | BG31: 失敗時 | BK31: 成功時 | BO31: 失敗時 | BS31: 成功時 | BW31: 失敗時
C32: 変換前ファイル | L32: 共通処理の出力、変換処理の入力ファイル。IDOC形式。 | AE32: 有 | AG32: 有 | AI32: 共通処理 | AM32: ETL(変換) | AQ32: - | AU32: ETL(変換) | AY32: - | BC32: ETL(変換) | BG32: - | BK32: 共通処理 | BO32: - | BS32: - | BW32: -
C33: 変換後ファイル | L33: 変換処理の出力、投入処理の入力ファイル。IDOC形式。 | AE33: 有 | AG33: 有 | AI33: ETL(変換) | AM33: ETL(投入) | AQ33: - | AU33: ETL(投入) | AY33: - | BC33: ETL(投入) | BG33: - | BK33: ETL(変換) | BO33: - | BS33: - | BW33: -
C34: ※ 標準と異なるファイル操作を指定したい場合のみ、AE～BZ列の内容を変更してください。標準のファイル操作については、インターフェース開発方針「4.2. 連携方式概要」を参照。
B36: ③ | C36: 順序制御
C37: ・ | D37: FIFO（受信した順番に連携する） | O37: ※FIFOではない個別の並び替え要件がある場合には、ソートのキーとなる項目および昇順/降順、複数ある場合には優先順序を明記すること。
B39: ④ | C39: トランザクション制御
C40: ・ | D40: 処理の開始時に対象となる全データを１つのトランザクションとして処理する。
A44: 3 | B44: 総IF毎の個別処理
B45: ① | C45: 連携元
C46: プロトコル | H46: ALE/IDOC
C47: No | E47: マージ版No | L47: 送信元情報 | T47: 送信先情報 | AA47: 抽出条件 | AL47: 備考・特記事項
C49: 1 | E49: 9999 | L49: ERP(S/4) | S49: ⇔ | T49: データ連携基盤 | AA49: なし
C50: 2
C51: 3
B53: ② | C53: 連携先
...

Sheet 対象IF一覧(IDOC→MQ)
A1: IFID | M1: インターフェース名称
A2: =IF(表紙!D16<>"",表紙!D16,"") | M2: =IF(表紙!D17<>"",表紙!D17,"")
A4: 1 | B4: 代表IF基本情報
B5: ① | C5: 連携元
C6: プロトコル | H6: ALE/IDOC
C7: メッセージタイプ | N7: 基本タイプ.拡張タイプ | X7: 備考・特記事項
B10: ② | C10: 連携先
C11: プロトコル | H11: IBMMQ
C12: メッセージフォーマット | R12: レコード長 | X12: 備考・特記事項
C13: 固定長 | R13: 10000
C15: プロトコル | H15: MSMQ
C16: メッセージフォーマット | R16: レコード長 | X16: 備考・特記事項
C17: XML | R17: ー | X17: [フォーマットに "XML" を選択する場合] XSD File： XXXXXXXXXXXXXXXXXXXXXXXXXX.xsd （または同等の情報が得られる資料へのリンクを明記）
A19: 2 | B19: 代表IF単位での共通処理
B20: ① | C20: 実行タイミング
C21: 実行場所 | J21: 処理名 | Q21: 起動契機 | X21: 連携区分 | AE21: 再処理単位 | AL21: 備考・特記事項
C22: 連携元(KIC) | J22: IDOC生成 | Q22: 時間指定 | X22: 差分 | AE22: トランザクション
C23: 連携元(KIC) | J23: IDOC送信 | Q23: ジョブ連携 | X23: 全件 | AE23: トランザクション
C24: データ連携基盤 | J24: ETL(抽出) | Q24: 随時 | X24: 全件 | AE24: トランザクション
C25: データ連携基盤 | J25: ETL(変換) | Q25: ファイル検知 | X25: 全件 | AE25: トランザクション
C26: データ連携基盤 | J26: ETL(投入) | Q26: ジョブ連携 | X26: 全件 | AE26: トランザクション
C27: 連携先 | J27: メッセージ取得 | Q27: 任意 | X27: 全件 | AE27: トランザクション
B30: ② | C30: ファイル操作
C31: パターン：IDOC → MQ
C32: ファイル種別 | L32: 説明 | AE32: 有無 | AG32: 複数世代 | AI32: 入出力 | AQ32: バックアップ | BC32: 削除 | BK32: リネーム：世代番号付与 | BS32: リネーム：FTP送達保証
AI33: 出力 | AM33: 入力 | AQ33: 事前(前回分) | AU33: 成功時 | AY33: 失敗時 | BC33: 成功時 | BG33: 失敗時 | BK33: 成功時 | BO33: 失敗時 | BS33: 成功時 | BW33: 失敗時
C34: 変換前ファイル | L34: 共通処理の出力、変換処理の入力ファイル。IDOC形式。 | AE34: 有 | AG34: 有 | AI34: 共通処理 | AM34: ETL(変換) | AQ34: - | AU34: ETL(変換) | AY34: - | BC34: ETL(変換) | BG34: - | BK34: 共通処理 | BO34: - | BS34: - | BW34: -
C35: 変換後ファイル | L35: 変換処理の出力、投入処理の入力ファイル。 | AE35: 有 | AG35: 有 | AI35: ETL(変換) | AM35: ETL(投入) | AQ35: - | AU35: ETL(投入) | AY35: - | BC35: ETL(投入) | BG35: - | BK35: ETL(変換) | BO35: - | BS35: - | BW35: -
C36: MQメッセージ(連携先) | L36: データ連携基盤が連携先向けのリモートキューにPUTしたメッセージ。 | AE36: 有 | AG36: 有 | AI36: ETL(投入) | AM36: 連携先 | AQ36: - | AU36: - | AY36: - | BC36: - | BG36: - | BK36: - | BO36: - | BS36: - | BW36: -
C37: ※ 標準と異なるファイル操作を指定したい場合のみ、AE～BZ列の内容を変更してください。標準のファイル操作については、インターフェース開発方針「4.2. 連携方式概要」を参照。
B39: ③ | C39: 順序制御
C40: ・ | D40: FIFO（受信した順番に連携する） | O40: ※FIFOではない個別の並び替え要件がある場合には、ソートのキーとなる項目および昇順/降順、複数ある場合には優先順序を明記すること。
B42: ④ | C42: トランザクション制御
C43: ・ | D43: 処理の開始時に対象となる全データを１つのトランザクションとして処理する。
A47: 3 | B47: 総IF毎の個別処理
B48: ① | C48: 連携元
C49: プロトコル | H49: ALE/IDOC
C50: No | E50: マージ版No | L50: 送信元情報 | T50: 送信先情報 | AA50: 抽出条件 | AL50: 備考・特記事項
C52: 1 | E52: 1000 | L52: ERP(S/4) | S52: ⇒ | T52: データ連携基盤 | AA52: なし | AL52: 堺工場向け
C53: 2 | E53: 2000 | L53: ERP(S/4) | S53: ⇒ | T53: データ連携基盤 | AA53: なし | AL53: 臨海工場向け
...

Sheet 対象IF一覧(MQ→IDOC)
A1: IFID | M1: インターフェース名称
A2: =IF(表紙!D16<>"",表紙!D16,"") | M2: =IF(表紙!D17<>"",表紙!D17,"")
A4: 1 | B4: 代表IF基本情報
B5: ① | C5: 連携元
C6: プロトコル | H6: IBMMQ
C7: メッセージフォーマット | R7: レコード長 | X7: 備考・特記事項
C8: 固定長 | R8: 10000
C10: プロトコル | H10: MSMQ
C11: メッセージフォーマット | R11: レコード長 | X11: 備考・特記事項
C12: XML | R12: ー | X12: [フォーマットに "XML" を選択する場合] XSD File： XXXXXXXXXXXXXXXXXXXXXXXXXX.xsd （または同等の情報が得られる資料へのリンクを明記）
B14: ② | C14: 連携先
C15: プロトコル | H15: ALE/IDOC
C16: メッセージタイプ | N16: 基本タイプ.拡張タイプ | X16: 備考・特記事項
A19: 2 | B19: 代表IF単位での共通処理
B20: ① | C20: 実行タイミング
C21: 実行場所 | J21: 処理名 | Q21: 起動契機 | X21: 連携区分 | AE21: 再処理単位 | AL21: 備考・特記事項
C22: 連携元 | J22: メッセージ送信 | Q22: 任意 | X22: 差分 | AE22: トランザクション
C23: データ連携基盤 | J23: ETL(抽出) | Q23: 随時 | X23: 全件 | AE23: トランザクション
C24: データ連携基盤 | J24: ETL(変換) | Q24: ファイル検知 | X24: 全件 | AE24: トランザクション
C25: データ連携基盤 | J25: ETL(投入) | Q25: ジョブ連携 | X25: 全件 | AE25: トランザクション
C26: 連携先(KIC) | J26: IDOC解析 | Q26: 時間指定 | X26: 全件 | AE26: トランザクション
C27: 連携先(KIC) | J27: データ格納 | Q27: 随時 | X27: 全件 | AE27: トランザクション
B30: ② | C30: ファイル操作
C31: パターン：MQ → IDOC
C32: ファイル種別 | L32: 説明 | AE32: 有無 | AG32: 複数世代 | AI32: 入出力 | AQ32: バックアップ | BC32: 削除 | BK32: リネーム：世代番号付与 | BS32: リネーム：FTP送達保証
AI33: 出力 | AM33: 入力 | AQ33: 事前(前回分) | AU33: 成功時 | AY33: 失敗時 | BC33: 成功時 | BG33: 失敗時 | BK33: 成功時 | BO33: 失敗時 | BS33: 成功時 | BW33: 失敗時
C34: MQメッセージ(連携元) | L34: 連携元がデータ連携基盤向けのリモートキューにPUTしたメッセージ。 | AE34: 有 | AG34: 有 | AI34: 連携元 | AM34: ETL(抽出) | AQ34: - | AU34: - | AY34: - | BC34: ETL(抽出) | BG34: - | BK34: - | BO34: - | BS34: - | BW34: -
C35: 変換前ファイル | L35: 抽出処理の出力、変換処理の入力ファイル。 | AE35: 有 | AG35: 有 | AI35: ETL(抽出) | AM35: ETL(変換) | AQ35: - | AU35: ETL(変換) | AY35: - | BC35: ETL(変換) | BG35: - | BK35: ETL(抽出) | BO35: - | BS35: - | BW35: -
C36: 変換後ファイル | L36: 変換処理の出力、投入処理の入力ファイル。IDOC形式。 | AE36: 有 | AG36: 有 | AI36: ETL(変換) | AM36: ETL(投入) | AQ36: - | AU36: ETL(投入) | AY36: - | BC36: ETL(投入) | BG36: - | BK36: ETL(変換) | BO36: - | BS36: - | BW36: -
C37: ※ 標準と異なるファイル操作を指定したい場合のみ、AE～BZ列の内容を変更してください。標準のファイル操作については、インターフェース開発方針「4.2. 連携方式概要」を参照。
B39: ③ | C39: 順序制御
C40: ・ | D40: FIFO（受信した順番に連携する） | O40: ※FIFOではない個別の並び替え要件がある場合には、ソートのキーとなる項目および昇順/降順、複数ある場合には優先順序を明記すること。
B42: ④ | C42: トランザクション制御
C43: ・ | D43: IDOCの文書番号は、インタフェース対象となるメッセージ１件につき１つのユニークな番号を割り当てて連携を行う。
D44: ※ ERP(S/4)側の取り込み処理でコミットを発行する単位で文書番号を分けること。
A47: 3 | B47: 総IF毎の個別処理
B48: ① | C48: 連携元
C49: プロトコル | H49: MSMQ
C50: No | E50: マージ版No | L50: 送信元情報 | T50: 送信先情報 | AA50: キュー名 | AG50: ラベル | AM50: 抽出条件 | AX50: 文字コード | BC50: トランザクション | BH50: ジャーナル | BM50: 記憶域の最大サイズ | BU50: 認証 | BW50: 0件時 送信 | BZ50: 備考・特記事項
BM51: メッセージ | BQ51: ジャーナル
...

Sheet 対象IF一覧(IDOC→ODBC)
A1: IFID | M1: インターフェース名称
A2: =IF(表紙!D16<>"",表紙!D16,"") | M2: =IF(表紙!D17<>"",表紙!D17,"")
A4: 1 | B4: 代表IF基本情報
B5: ① | C5: 連携元
C6: プロトコル | H6: ALE/IDOC
C7: メッセージタイプ | N7: 基本タイプ.拡張タイプ | X7: 備考・特記事項
B10: ② | C10: 連携先
C11: プロトコル | H11: ODBC
C12: テーブル名 | N12: IF用ワークTB | X12: 備考・特記事項
A16: 2 | B16: 代表IF単位での共通処理
B17: ① | C17: 実行タイミング
C18: 実行場所 | J18: 処理名 | Q18: 起動契機 | X18: 連携区分 | AE18: 再処理単位 | AL18: 備考・特記事項
C19: 連携元(KIC) | J19: IDOC生成 | Q19: 時間指定 | X19: 差分 | AE19: トランザクション
C20: 連携元(KIC) | J20: IDOC送信 | Q20: ジョブ連携 | X20: 全件 | AE20: トランザクション
C21: データ連携基盤 | J21: ETL(抽出) | Q21: 随時 | X21: 全件 | AE21: トランザクション
C22: データ連携基盤 | J22: ETL(変換) | Q22: ファイル検知 | X22: 全件 | AE22: トランザクション
C23: データ連携基盤 | J23: ETL(投入) | Q23: ジョブ連携 | X23: 差分 | AE23: トランザクション | AL23: IFワークTBのレコードを全件置換でインタフェースする。 完了後に、ワークTBとターゲットTBとマージして差分の反映を行う。
B26: ② | C26: ファイル操作
C27: パターン：IDOC → ODBC
C28: ファイル種別 | L28: 説明 | AE28: 有無 | AG28: 複数世代 | AI28: 入出力 | AQ28: バックアップ | BC28: 削除 | BK28: リネーム：世代番号付与 | BS28: リネーム：FTP送達保証
AI29: 出力 | AM29: 入力 | AQ29: 事前(前回分) | AU29: 成功時 | AY29: 失敗時 | BC29: 成功時 | BG29: 失敗時 | BK29: 成功時 | BO29: 失敗時 | BS29: 成功時 | BW29: 失敗時
C30: 変換前ファイル | L30: 共通処理の出力、変換処理の入力ファイル。IDOC形式。 | AE30: 有 | AG30: 有 | AI30: 共通処理 | AM30: ETL(変換) | AQ30: - | AU30: ETL(変換) | AY30: - | BC30: ETL(変換) | BG30: - | BK30: 共通処理 | BO30: - | BS30: - | BW30: -
C31: 変換後ファイル | L31: 変換処理の出力、投入処理の入力ファイル。 | AE31: 有 | AG31: 有 | AI31: ETL(変換) | AM31: ETL(投入) | AQ31: - | AU31: ETL(投入) | AY31: - | BC31: ETL(投入) | BG31: - | BK31: ETL(変換) | BO31: - | BS31: - | BW31: -
C32: ※ 標準と異なるファイル操作を指定したい場合のみ、AE～BZ列の内容を変更してください。標準のファイル操作については、インターフェース開発方針「4.2. 連携方式概要」を参照。
B34: ③ | C34: 順序制御
C35: ・ | D35: FIFO（受信した順番に連携する） | O35: ※FIFOではない個別の並び替え要件がある場合には、ソートのキーとなる項目および昇順/降順、複数ある場合には優先順序を明記すること。
B37: ④ | C37: トランザクション制御
C38: ・ | D38: 処理の開始時に対象となる着信済データ(未連携分)を１つのトランザクションとして一括で処理する。
A42: 3 | B42: 総IF毎の個別処理
B43: ① | C43: 連携元
C44: プロトコル | H44: ALE/IDOC
C45: No | E45: マージ版No | L45: 送信元情報 | T45: 送信先情報 | AA45: 抽出条件 | AL45: 備考・特記事項
C47: 1 | E47: XXXX | L47: ERP(S/4) | S47: ⇒ | T47: データ連携基盤 | AA47: なし
B50: ② | C50: 連携先
C51: プロトコル | H51: ODBC
C52: No | E52: マージ版No | L52: 送信元情報 | T52: 送信先情報 | AA52: 抽出条件 | AL52: DSN | AS52: データベース名 | AZ52: データベース別名 | BG52: スキーマ名 | BN52: 備考・特記事項
C54: 1 | E54: XXXX | L54: データ連携基盤 | S54: ⇒ | T54: 農機国内DWH | AA54: なし | AL54: 本番：APROS | BN54: 農機国内DWH経由で下記システムにデータを連携する。 ・K-SCM（生販計画） ・K-SCM（管理経理）
AL55: 統合：APROSPRE
AL56: 結合：APROSSE
AL57: 試験：DWHSE | AS57: EROUTE | AZ57: DWHSE | BG57: DWHSE
...

Sheet 対象IF一覧(DB連携)
A1: IFID | M1: インターフェース名称
A2: =IF(表紙!D16<>"",表紙!D16,"") | M2: =IF(表紙!D17<>"",表紙!D17,"")
A4: 1 | B4: DB連携の接続情報
C5: DBMS | K5: テーブルID | V5: テーブル名称 | AH5: 備考・特記事項
C6: Pure HANA | K6: ZG01IFT2xxx | V6: ○○テーブル | AH6: ＸＸＸＸＸＸＸＸＸＸＸＸＸＸＸＸ
A8: 2 | B8: 総IF毎の接続情報
C9: マージ版No | K9: 接続元システム名 | V9: 説明 | AH9: 備考・特記事項
C10: 9001 | K10: K-SCM（管理経理） | AH10: ＸＸＸＸＸＸＸＸＸＸＸＸＸＸＸＸ
C11: 9002 | K11: K-SCM（生販計画） | AH11: ＸＸＸＸＸＸＸＸＸＸＸＸＸＸＸＸ
C12: 9003 | K12: K-SCM（統合調達） | AH12: ＸＸＸＸＸＸＸＸＸＸＸＸＸＸＸＸ
A15: 3 | B15: システムフロー（任意記載）
B19: ※ | C19: DB連携のインタフェースパターンでは、シート [項目マッピング][PWC設計] は不要。
B20: ※ | C20: 接続先のDB情報については、「1.DB連携の接続情報」欄に記載のテーブルIDに対するテーブル定義書を参照。それ以外に参照すべきドキュメントがある場合は、以下に記載。

Sheet PwC設計
A1: IFID | C1: インターフェース名称
A2: =IF(表紙!D16<>"",表紙!D16,"") | C2: =IF(表紙!D17<>"",表紙!D17,"")
A3: 変換処理
A5: 処理No.01
A20: 処理No.02

Sheet FMT変更履歴
A1: フォーマット変更履歴 | F1: レビュー | I1: 承認
A2: No. | B2: 変更日 | C2: 変更者 | D2: 変更箇所 | E2: 変更内容 | F2: ABレビュー者 | G2: 開発管理レビュー者 | H2: KBT事務局レビュー者 | I2: KBT事務局承認 | J2: 承認日
A3: R1.00 | B3: 43819 | C3: 奥村 | D3: 全文書 | E3: 初版
A4: R1.10 | B4: 43845 | C4: 西山 | D4: 対象IF一覧 | E4: [3.総IF毎の個別処理] から [IF名称] [業務パターン] の列を削除。 → 理由：総IFで異なることは想定されない。
D5: 対象IF一覧 | E5: [3.総IF毎の個別処理] のプロトコル [ALE/IDOC] の列 [パートナ番号] を [抽出条件] ないし [抽出条件] に変更。 → 理由：パートナー番号を条件とするのは例外的なパターンとなる一方、抽出条件や抽出条件を明記する欄がなかったため。
D6: 対象IF一覧 | E6: [3.総IF毎の個別処理] の [②連携先] の列 [抽出条件] を [抽出条件] に変更。 → 理由：連携先にデータを渡す条件なので、[抽出]との表現は不適切。
D7: 対象IF一覧 | E7: [文字コード/改行コード/括り文字/0件時のフォーマット] の設定欄を [1.代表IF基本情報] から [3.総IF毎の個別処理] に移動。 → 理由：総IFで異なる可能性が指摘されたため。
D8: 対象IF一覧 | E8: 列 [0件時のフォーマット] を [ヘッダ][空ファイル生成] に分割。 → 理由：ヘッダの要否はデータの件数とは直接の関係がない。
D9: 対象IF一覧 | E9: [1.代表IF基本情報] の列 [基本タイプ/拡張タイプ/メッセージタイプ/拡張メッセージタイプ] を統合。 → 理由①：IDOCに [拡張メッセージタイプ] という概念はない。 → 理由②：原則をユーザIDOCに寄せる方針。拡張タイプを意識するのは例外となるため。
D10: 対象IF一覧 | E10: [起動契機] に関する情報を [1.代表IF基本情報] から [2.代表IF単位での共通処理] に移動。 → 理由：処理に関する情報で合って基本情報ではないし、フォーマットとは記載したい粒度が異なる情報であるため。
D11: 対象IF一覧 | E11: 列位置を微調整。
D12: 対象IF一覧 | E12: 連携方式の組み合わせでテンプレートシートを分離。 → 理由：MQ等のテンプレートを追加するにあたり情報量が増えたことで、何を残して何を削除するべきなのかがわかりにくくなると懸念されたため。
D13: 対象IF一覧(SOAP→BAPI) | E13: シート追加。
D14: 対象IF一覧(IDOC→MQ) | E14: シート追加。
D15: 対象IF一覧(MQ→IDOC) | E15: シート追加。
D16: 対象IF一覧(FTP→MQ) | E16: シート追加。
D17: 対象IF一覧(MQ→FTP) | E17: シート追加。
A18: R1.20 | B18: 43880 | C18: 西山 | D18: 対象IF一覧(*) | E18: 「④ トランザクション制御」の記入欄を追加。
A19: R1.30 | B19: 43881 | C19: 伊東 | D19: 項目マッピング | E19: 「Byte数」⇒「文字数」に変更。
A20: R1.40 | B20: 43922 | C20: 西山 | D20: 対象IF一覧(*MQ*) | E20: MSMQ用のレイアウトを追加。
A21: R1.50 | B21: 43944 | C21: 吉住 | D21: 対象IF一覧(DB連携) | E21: シート追加。
A22: R1.60 | B22: 43964 | C22: 西山 | D22: 全シート | E22: シート [リスト] を追加。各選択項目(データの入力規則)について整理。
D23: IFレイアウト | E23: 項目「属性」に「日時」を追加。「日時」を選択する際は「書式設定」も指定する必要がある旨をメモに追記。注意喚起の条件付き書式設定を追加。
E24: 項目「文字種別」に「混在」を選択する場合、固定長のフォーマットを選択しないようにメモに注意事項を追記。注意喚起の条件付き書式設定を追加。
E25: 項目「符号」の記載例が不適切な指定になっていた（数値以外の項目に符号を付与する体裁になっていた）ためサンプルを修正。
D26: 対象IF一覧(*) | E26: IF方針として非推奨と規定されたことを踏まえて、「文字コード」の選択肢から「EBCDIC」を削除。
B27: 43977 | C27: 村田 | D27: 項目マッピング | E27: P列以降に対向先セッション用の列を追加。
C28: 西山 | D28: 対象IF一覧(*) | E28: FTPで扱うファイルのフォーマットに「XML」を追加。
E29: FTP/IBMMQで扱うフォーマットで「固定長」以外を選択した場合に、「レコード長」の記入欄がグレーアウトされるように変更。
A30: R1.70 | B30: 44011 | C30: 西山 | D30: 対象IF一覧(*) | E30: 連携元/先で選択可能なプロトコルを追加。
A31: R1.71 | B31: 44077 | C31: 西山 | D31: 対象IF一覧(SFTP→*) 対象IF一覧(*→SFTP) | E31: ・RR連携用にシート追加。 ・「対象IF一覧(FTP→FTP)」のシートは削除。
D32: 対象IF一覧(MQ→*) 対象IF一覧(*→MQ) | E32: ・Apriso MESが工場ごとに別インスタンスとなるとのことからテンプレート変更。 ・「4.システムフロー」の記載例を追加。
D33: 対象IF一覧(*) | E33: ・記載例の誤字を修正。（「牧方」との誤表記(枚方の間違い)あり） ・「抽出条件」の記載例が実情に沿っていなかったのを修正。
D34: 対象IF一覧(FTP→FTP) | E34: ・RRの変換マスタ連携で需要があるとのことだったのでシート復活。
A35: R1.72 | B35: 44099 | C35: 西山 | D35: 対象IF一覧(IDOC→ODBC) | E35: ・過渡期DB連携用(農機DWH経由のK-SCMとの連携を想定)にシート追加。
A36: R1.73 | B36: 44258 | C36: 西山 | D36: 対象IF一覧(MQ→FTP) 対象IF一覧(MQ→IDOC) | E36: ・データ連携基盤側のキュー名をAprisoの工場インスタンスごとに変更。

Sheet リスト
A1: 表紙 | B1: IFフォーマット | J1: 対象IF一覧 | U1: 項目マッピング
A2: 連携方式 | B2: Key | C2: 属性 | D2: 文字種別 | E2: 有り無し | F2: 小数部 | G2: 必須 | H2: 文字埋 | I2: 符号 | J2: プロトコル | K2: フォーマット | L2: 操作内容 | M2: 起動契機 | N2: 連携区分 | O2: 再処理単位 | P2: 文字コード | Q2: 改行コード | R2: 括り文字 | S2: 空ファイル生成 | T2: 有無 | U2: 項目属性 | V2: 桁数表記
A3: ファイル連携 | C3: 文字 | D3: 半角 | E3: 有り | F3: 固定 | H3: 無し | I3: 無 | J3: ALE/IDOC | K3: 可変長(タブ区切り) | L3: 取得 | M3: ジョブ連携 | N3: 全件 | O3: ALL | P3: UTF-8 | Q3: CR+LF | R3: なし | S3: 無 | T3: 有 | U3: 文字(半角のみ) | V3: 文字数
A4: Webサービス連携 | B4: ● | C4: 数値 | D4: 全角 | E4: 無し | F4: 省略 | G4: 〇 | H4: 前ゼロ | I4: 前 | J4: RFC/BAPI | K4: 可変長(カンマ区切り) | L4: 登録・変更・削除 | M4: ファイル検知 | N4: 差分 | O4: トランザクション | P4: ASCII | Q4: CR | R4: ダブルクォーテーション | S4: 有(通常) | T4: 無 | U4: 文字(全角のみ) | V4: Byte数
A5: メッセージ連携 | C5: 日付 | D5: 混在 | H5: 前スペース | I5: 後 | J5: FTP | K5: 固定長 | L5: 登録専用 | M5: 時間指定 | O5: レコード | P5: Shift-JIS | Q5: LF | R5: シングルクォーテーション | S5: 有(0バイト) | U5: 文字(全角半角混在)
A6: SAP直接連携 | C6: 時刻 | H6: 後スペース | J6: SFTP | K6: XML | L6: 変更専用 | M6: 随時 | P6: EUC-JP | R6: その他(備考参照) | U6: 数値(符号付き)
A7: DB連携 | C7: 日付+時刻 | J7: IBMMQ | K7: その他(備考参照) | L7: 削除専用 | M7: 任意 | U7: 数値(符号なし)
J8: MSMQ | M8: 要検討 | U8: 日付
J9: ODBC | M9: その他(備考参照) | U9: 時刻
J10: SOAP | U10: 日付+時刻

Sheet 圧縮品番
B7: 1.4桁圧縮品番の設定
B8: 圧縮品番の構成は英字1桁＋数字3桁の4桁です。
B9: 設定方法は下記の通り
C10: 品番(上1桁) | I10: ○英字1桁 | W10: △△△数字3桁
C11: ゼロ | I11: 品番(上7桁)の合計÷20 の余りを求める | W11: 品番（2桁目 ＋ 5桁目 ＋ 8桁目）＊100 → Ａ
J12: ・余りがｾﾞﾛは、余り20として扱う | W12: 品番（3桁目 ＋ 6桁目 ＋ 9桁目）＊10 → Ｂ
W13: 品番（4桁目 ＋ 7桁目 ＋ 10桁目）＊1 → Ｃ
C14: ゼロ以外 | I14: 品番(上6桁)の合計÷20 の余りを求める | W14: 品番（1桁目 ＋ 4桁目 ＋ 7桁目）＊100 → Ａ
J15: ・余りがｾﾞﾛは、余り20として扱う | W15: 品番（2桁目 ＋ 5桁目 ＋ 8桁目）＊10 → Ｂ
W16: 品番（3桁目 ＋ 6桁目 ＋ 9桁目）＊1 → Ｃ
C17: 設定値 | I17: 余りの値に該当する【英字テーブル】の英字 | W17: Ａ＋Ｂ＋Ｃ
B18: ex) | E18: 品番
D19: 120001234 | I19: （0+1+2+0+0+0+1）÷20 | W19: （1+0+2）*100＝300
M20: 余り＝4 | P20: → | Q20: Ｄ' | W20: （2+0+3）*10 ＝ 50 | AE20: 355
W21: （0+1+4）*1 ＝ 5
D23: C120001234 | I23: （3+1+2+0+0+0）÷20 | W23: （3+0+1）*100＝400
M24: 余り＝6 | P24: → | Q24: Ｆ' | W24: （1+0+2）*10 ＝ 30 | AE24: 435
W25: （2+0+3）*1 ＝ 5
H27: ※ | I27: 先に品番(n)が数値で無い場合は、【英字テーブル】に該当する余りの数値を使用する。（Cなら3）
I28: 該当する英字が存在しない場合は、ｾﾞﾛとして扱う。
B29: 英字テーブル
B30: 数字 | F30: 1 | G30: 2 | H30: 3 | I30: 4 | J30: 5 | K30: 6 | L30: 7 | M30: 8 | N30: 9 | O30: 10 | P30: 11 | Q30: 12 | R30: 13 | S30: 14 | T30: 15 | U30: 16 | V30: 17 | W30: 18 | X30: 19 | Y30: 20
B31: 英字 | F31: A | G31: B | H31: C | I31: D | J31: E | K31: F | L31: G | M31: H | N31: J | O31: K | P31: L | Q31: M | R31: N | S31: P | T31: R | U31: S | V31: T | W31: W | X31: Y | Y31: Z

Sheet 文書変更履歴
A1: 文書変更履歴 | F1: レビュー | I1: 承認
A2: No. | B2: 変更日 | C2: 変更者 | D2: 変更箇所 | E2: 変更内容 | F2: TISレビュー者 | G2: 開発管理レビュー者 | H2: KBTレビュー者 | I2: KBT承認 | J2: 承認日
A3: 0.01 | B3: 46013 | C3: TIS竹田 | D3: 全文書 | E3: 初版 | F3: TIS丸山
A4: 0.80 | B4: 46014 | C4: TIS奥川 | D4: ー | E4: 要件定義工程納品のためバージョンアップ
A5: 0.81 | B5: 46055 | C5: TIS齊藤 | D5: 表紙 | E5: IFID訂正：IF0120→IFZ9000120
A6: 0.81 | B6: 46055 | C6: TIS齊藤 | D6: 項目マッピング | E6: S0100連携元変更：ADRC-NAME3＋NAME4→ADRC-NAME1＋NAME2 S0110連携元変更：ADRC-HOME_CITY→ADRC-CITY1＋STREET S0170連携元変更：ADRC-NAME3＋NAME4→ADRC-NAME1＋NAME2 S0500変換仕様修正：品目階層の7～9桁目→11～18桁目の下3桁 S0510変換仕様修正：品目階層の4～6桁目→6～10桁目の下3桁 S0520変換仕様修正：品目階層の1～3桁目→1～5桁目の下3桁 S0550連携元変更：MARA-MATKL→MVKE-MTPOS
